Workbook

Sheet Meta
A1: Autor: | B1: Brandon Andrés Jiménez Nieto
A3: Clases (orden mlp.classes_):
A4: Adelie | B4: Chinstrap | C4: Gentoo
A6: Mapa 'island' (valor→code)
A7: island_valor | B7: island_code
A8: Biscoe | B8: 0
A9: Dream | B9: 1
A10: Torgersen | B10: 2
A12: Mapa 'culmen_length_mm' (valor→code)
A13: culmen_length_mm_valor | B13: culmen_length_mm_code
A14: 32.1 | B14: 0
A15: 33.1 | B15: 1
A16: 33.5 | B16: 2
A17: 34 | B17: 3
A18: 34.4 | B18: 4
A19: 34.5 | B19: 5
A20: 34.6 | B20: 6
A21: 35 | B21: 7
A22: 35.1 | B22: 8
A23: 35.2 | B23: 9
A24: 35.3 | B24: 10
A25: 35.5 | B25: 11
... A176: 59.6 | B176: 162
A178: Mapa 'culmen_depth_mm' (valor→code)
A179: culmen_depth_mm_valor | B179: culmen_depth_mm_code
A180: 13.1 | B180: 0
A181: 13.2 | B181: 1
A182: 13.3 | B182: 2
A183: 13.4 | B183: 3
A184: 13.5 | B184: 4
A185: 13.6 | B185: 5
A186: 13.7 | B186: 6
A187: 13.8 | B187: 7
A188: 13.9 | B188: 8
A189: 14 | B189: 9
A190: 14.1 | B190: 10
A191: 14.2 | B191: 11
... A258: 21.5 | B258: 78
A260: Mapa 'flipper_length_mm' (valor→code)
A261: flipper_length_mm_valor | B261: flipper_length_mm_code
...

Sheet Pesos
A1: W1 (n_features x n_hidden1)
A2: 0.15706136 | B2: 0.085886587 | C2: 0.088913817 | D2: -0.00032081976 | E2: 0.13233212 | F2: -0.0064702457 | G2: -0.18912628 | H2: -0.076115637 | I2: -0.0057485757 | J2: 0.10634977 | K2: 0.0028829201 | L2: -0.18955488 | M2: 0.16411574 | N2: 3.4223533e-08 | O2: 0.0054049247 | P2: -0.073120094 | Q2: 0.23761195 | R2: -0.085970084 | S2: -0.015176349 | T2: -0.072426336 | U2: -0.064563508 | V2: -0.075034894 | W2: 0.11313702 | X2: -0.022550903 | Y2: 0.24528886 | Z2: -0.058925707 | AA2: 0.10230642 | AB2: -0.1056966 | AC2: 0.059272603 | AD2: 0.20825173 | AE2: 0.10986675 | AF2: -0.20554384 | AG2: -0.07161852 | AH2: -0.18578146 | AI2: -0.013332255 | AJ2: 0.12836375 | AK2: 0.13545918 | AL2: 0.12257911 | AM2: -0.19680135 | AN2: -0.16827273 | AO2: 0.0076461003 | AP2: 0.055146783 | AQ2: 0.002269407 | AR2: -0.1000446 | AS2: 0.20151509 | AT2: 0.10781178 | AU2: 0.084356945 | AV2: -0.16252937 | AW2: -0.15563001 | AX2: 0.1991215 | AY2: -0.17620881 | AZ2: -0.041724819 | BA2: 0.056557281 | BB2: -0.21612549 | BC2: 0.010313153 | BD2: 0.14313773 | BE2: 0.25970021 | BF2: 0.0023714159 | BG2: -0.10618618 | BH2: -0.0054679871 | BI2: 0.22238341 | BJ2: -0.19824538 | BK2: 0.20350721 | BL2: 0.069989757 | BM2: -6.3546785e-05 | BN2: 0.0065960182 | BO2: -0.20625932 | BP2: -0.07194073 | BQ2: 0.0031875489 | BR2: -0.14651609 | BS2: -0.070172823 | BT2: -0.16261403 | BU2: -0.012746647 | BV2: 0.057145216 | BW2: 0.17278837 | BX2: 0.017722984 | BY2: -0.0035424815 | BZ2: -0.13569255 | CA2: 0.016899601 | CB2: -0.045824192 | CC2: 0.021239065 | CD2: 0.058058972 | CE2: -0.19218212 | CF2: 0.18266865 | CG2: -0.039373536 | CH2: 0.28678671 | CI2: 0.054725064 | CJ2: -0.06263034 | CK2: -0.034900198 | CL2: 0.20554679 | CM2: 0.14079345 | CN2: 0.10991737 | CO2: 0.26010577 | CP2: 0.27311017 | CQ2: -0.14108875 | CR2: -0.24196537 | CS2: 0.23766089 | CT2: -0.16947084 | CU2: 0.17409882 | CV2: -0.075409198
A3: -0.015834308 | B3: 0.13340275 | C3: 0.12281265 | D3: -0.079600355 | E3: -0.086612632 | F3: -0.018710157 | G3: 0.23150438 | H3: -0.001816589 | I3: -0.16847742 | J3: 0.11110321 | K3: -0.032078222 | L3: -0.093022058 | M3: 0.12142465 | N3: -0.052132357 | O3: -0.0076994296 | P3: -0.00054428053 | Q3: -0.0088340833 | R3: 0.18310445 | S3: 0.22414817 | T3: -0.023716232 | U3: -0.069253548 | V3: 0.092834901 | W3: 0.015516759 | X3: -0.015801311 | Y3: -0.072250482 | Z3: -0.070691003 | AA3: 0.22745621 | AB3: 0.11107195 | AC3: 0.24514289 | AD3: 0.012667472 | AE3: 0.14412615 | AF3: 0.22957476 | AG3: -0.052545455 | AH3: -0.18830102 | AI3: -0.19822837 | AJ3: 0.02925747 | AK3: 0.037283828 | AL3: -0.1944274 | AM3: 0.075884242 | AN3: -0.030684027 | AO3: -0.080021369 | AP3: -0.057990174 | AQ3: -0.0092317075 | AR3: -0.025751051 | AS3: 0.014658225 | AT3: 0.014934135 | AU3: 0.16312019 | AV3: -0.072921834 | AW3: -0.024744364 | AX3: 0.10480486 | AY3: -0.24302408 | AZ3: -0.20421072 | BA3: -0.03782813 | BB3: 0.037365865 | BC3: 0.046169858 | BD3: 0.12451668 | BE3: 0.23669814 | BF3: -0.04797797 | BG3: -0.10462959 | BH3: -0.21264595 | BI3: -0.1641506 | BJ3: -0.23275623 | BK3: 0.17591008 | BL3: -8.0314276e-08 | BM3: -0.028356989 | BN3: -0.070697736 | BO3: 0.17691424 | BP3: -0.11261498 | BQ3: -0.017659553 | BR3: 0.11057484 | BS3: -0.015121447 | BT3: -0.01169802 | BU3: -0.10738504 | BV3: 0.10103938 | BW3: 0.075363628 | BX3: -0.00018063115 | BY3: -0.069831772 | BZ3: 0.045648651 | CA3: -0.0032349415 | CB3: -0.23629076 | CC3: -0.017037421 | CD3: -0.060810857 | CE3: 0.22234935 | CF3: 0.17607337 | CG3: 0.22768974 | CH3: -0.16190662 | CI3: -4.29043e-05 | CJ3: -0.15229694 | CK3: -0.12080801 | CL3: 0.12749013 | CM3: 0.15083394 | CN3: 0.063238774 | CO3: -0.16720139 | CP3: -0.012368675 | CQ3: 0.18983819 | CR3: -0.24446943 | CS3: 0.086830239 | CT3: 0.18084021 | CU3: 0.20206195 | CV3: 0.0016888564
A4: 0.016905151 | B4: -0.061499101 | C4: 0.10301471 | D4: -0.003463486 | E4: 0.16027059 | F4: -0.13531977 | G4: -0.031976271 | H4: 0.030440833 | I4: 0.092765591 | J4: 0.018533996 | K4: -0.056563354 | L4: 0.038049148 | M4: 0.017813219 | N4: -0.018845048 | O4: 0.25313491 | P4: -0.051643492 | Q4: -0.026419906 | R4: -0.098299298 | S4: 0.23035697 | T4: 0.145198 | U4: -0.042755842 | V4: -0.16867481 | W4: -0.14014483 | X4: -0.015875526 | Y4: 0.046939429 | Z4: -0.025941268 | AA4: -0.18408792 | AB4: -0.090317249 | AC4: -0.1085898 | AD4: -0.15195562 | AE4: -0.18822182 | AF4: 0.10744255 | AG4: -0.03147245 | AH4: 0.1408496 | AI4: 0.21969189 | AJ4: -0.0042612504 | AK4: -0.046161852 | AL4: 0.00079865216 | AM4: -0.064649838 | AN4: 0.14987585 | AO4: 0.15836003 | AP4: 0.20992254 | AQ4: -0.01472383 | AR4: 0.24864263 | AS4: -0.16221824 | AT4: -0.0036554071 | AU4: 0.020951415 | AV4: -0.024557606 | AW4: 0.17239638 | AX4: -0.20936915 | AY4: 0.074060721 | AZ4: -0.063329206 | BA4: -0.072402313 | BB4: -0.048108951 | BC4: 0.24261892 | BD4: -0.16244525 | BE4: 0.074760603 | BF4: -0.083765637 | BG4: 0.23731784 | BH4: 0.09212618 | BI4: 0.0079291519 | BJ4: 0.081342791 | BK4: -0.19363368 | BL4: -6.8734931e-07 | BM4: -0.024021643 | BN4: -0.0029434735 | BO4: 0.087048685 | BP4: 0.10468561 | BQ4: -0.067384533 | BR4: -0.1979707 | BS4: -0.073943539 | BT4: 0.19428269 | BU4: -0.1758326 | BV4: -0.089086294 | BW4: 0.21597688 | BX4: -0.0036952903 | BY4: 1.0423606e-06 | BZ4: -0.044831712 | CA4: -0.00099515389 | CB4: 0.042415779 | CC4: -0.064235983 | CD4: 0.12093456 | CE4: -0.076324889 | CF4: 0.00079583129 | CG4: -0.20547286 | CH4: 0.16568955 | CI4: -0.00010845399 | CJ4: 0.21194628 | CK4: 0.13062361 | CL4: -0.0047723761 | CM4: 0.053721015 | CN4: -0.030321017 | CO4: 0.16562276 | CP4: 0.022625872 | CQ4: 0.11575419 | CR4: 0.1149553 | CS4: -0.082392756 | CT4: -0.038535595 | CU4: 0.036468103 | CV4: -0.024219433
A5: -0.039932092 | B5: 0.23161627 | C5: 0.03747647 | D5: 1.0201877e-06 | E5: 0.096568363 | F5: 0.10057312 | G5: -0.19866966 | H5: 0.12098573 | I5: -0.059205842 | J5: 0.19285234 | K5: -0.017551814 | L5: -0.10253696 | M5: -0.062709438 | N5: -0.08568926 | O5: 0.20883056 | P5: -0.053771072 | Q5: 0.054938084 | R5: 0.036101682 | S5: 0.14148437 | T5: -0.13065829 | U5: 0.15640929 | V5: -0.058160695 | W5: 0.062058849 | X5: -0.057826131 | Y5: -0.10895646 | Z5: 0.053993844 | AA5: 0.14302224 | AB5: -0.19658171 | AC5: -0.048655752 | AD5: 0.10438594 | AE5: 0.10198207 | AF5: -0.023705067 | AG5: -0.00080046025 | AH5: -0.16511169 | AI5: -0.20632736 | AJ5: -0.17273173 | AK5: -0.22377508 | AL5: 0.20385575 | AM5: 0.14976312 | AN5: -0.2018482 | AO5: -0.063564717 | AP5: -0.098836974 | AQ5: 1.1390818e-06 | AR5: 0.15508679 | AS5: 0.15225484 | AT5: 0.1559079 | AU5: 0.0051572634 | AV5: 0.11889028 | AW5: -0.053529708 | AX5: 0.21305201 | AY5: -0.054612398 | AZ5: -0.20564568 | BA5: 0.027371949 | BB5: -0.1381332 | BC5: 0.076396552 | BD5: 0.040849364 | BE5: 0.034692986 | BF5: 0.12416175 | BG5: -0.081356622 | BH5: -0.067940969 | BI5: 0.17421505 | BJ5: 0.20706448 | BK5: 0.084329985 | BL5: -0.080950224 | BM5: 0.0037791838 | BN5: 0.0021417842 | BO5: -0.21588409 | BP5: -0.24097183 | BQ5: -0.010460809 | BR5: 0.10754633 | BS5: -0.04029208 | BT5: -0.00015755797 | BU5: 0.15927263 | BV5: -0.10906684 | BW5: 0.24439749 | BX5: -0.044128503 | BY5: -0.043292607 | BZ5: -0.075967401 | CA5: -0.0058784805 | CB5: -0.02587756 | CC5: -0.012451045 | CD5: 0.12478468 | CE5: 0.18770536 | CF5: 0.1341194 | CG5: 0.088160981 | CH5: 0.12596796 | CI5: -0.059046537 | CJ5: 0.22677842 | CK5: 0.099335554 | CL5: -0.15991791 | CM5: -0.032496329 | CN5: -0.14393343 | CO5: 0.14222706 | CP5: -0.12557252 | CQ5: -0.10854086 | CR5: 0.19288397 | CS5: 0.17331505 | CT5: 0.058511532 | CU5: 0.2183418 | CV5: -0.034658818
A6: -0.13533291 | B6: 0.042156682 | C6: 0.092547829 | D6: 4.8523342e-05 | E6: -0.18490948 | F6: -0.05326661 | G6: -0.094756006 | H6: -0.13036844 | I6: -0.19340791 | J6: -0.14321753 | K6: -0.003933338 | L6: 0.12038615 | M6: -0.042417727 | N6: 0.047202818 | O6: -0.08860126 | P6: 0.01250669 | Q6: 0.19917895 | R6: 0.15834073 | S6: 0.057670231 | T6: 0.084851117 | U6: 0.15297657 | V6: -0.098206839 | W6: 0.10833364 | X6: 0.02952528 | Y6: -0.075439973 | Z6: -0.0019690772 | AA6: -0.11479718 | AB6: 0.13596003 | AC6: -0.055929041 | AD6: 0.19789255 | AE6: 0.21418341 | AF6: -0.2161227 | AG6: -3.777268e-08 | AH6: -0.074443636 | AI6: -0.074971088 | AJ6: -0.085705931 | AK6: 0.084450665 | AL6: 0.12428117 | AM6: 0.004748475 | AN6: -0.022947762 | AO6: -0.034806183 | AP6: 0.016231965 | AQ6: -0.064712447 | AR6: -0.18374036 | AS6: -0.060889956 | AT6: -0.12444609 | AU6: -0.16149601 | AV6: 0.2270218 | AW6: 0.031548983 | AX6: -0.061043472 | AY6: -0.062446584 | AZ6: 0.21982329 | BA6: -0.012542531 | BB6: 0.18484056 | BC6: 0.1853238 | BD6: 0.2159225 | BE6: -0.043375238 | BF6: -0.0017767998 | BG6: -0.091520398 | BH6: 0.13881155 | BI6: 0.11849352 | BJ6: 0.19688039 | BK6: 0.051795716 | BL6: -0.084780197 | BM6: -0.052281541 | BN6: -0.0098438789 | BO6: 0.22071934 | BP6: -0.13506846 | BQ6: -2.4725648e-06 | BR6: 0.19755315 | BS6: 0.026096341 | BT6: 0.21098574 | BU6: 0.020979384 | BV6: 0.089650213 | BW6: 0.12244996 | BX6: -0.069141625 | BY6: -3.0489387e-05 | BZ6: 0.048266361 | CA6: -0.016859267 | CB6: -0.20878346 | CC6: -4.7889718e-06 | CD6: -0.099750605 | CE6: 0.13630091 | CF6: 0.11431269 | CG6: 0.088050332 | CH6: 0.22687186 | CI6: -0.023069728 | CJ6: 0.046534908 | CK6: 0.11613052 | CL6: 0.046002918 | CM6: 0.050365512 | CN6: -0.019499234 | CO6: 0.23574743 | CP6: 0.087223099 | CQ6: -0.057763582 | CR6: -0.078716401 | CS6: 0.19707064 | CT6: 0.041956303 | CU6: 0.14474277 | CV6: -0.070695482
A7: 0.05618387 | B7: 0.14130135 | C7: -0.11067254 | D7: -0.026324817 | E7: -0.19952948 | F7: -0.038596834 | G7: -0.11469319 | H7: -0.25666196 | I7: -6.4587819e-09 | J7: -0.0062269899 | K7: 7.4499289e-07 | L7: 0.17440117 | M7: 0.19793607 | N7: 0.0027002602 | O7: -0.11321979 | P7: -0.020771469 | Q7: 0.21728229 | R7: -0.2091823 | S7: 0.18841378 | T7: 0.017675554 | U7: 0.10539164 | V7: -0.09322803 | W7: 0.10677802 | X7: 2.3421009e-05 | Y7: -0.031315023 | Z7: -0.019608193 | AA7: -0.18488843 | AB7: -0.2481486 | AC7: 0.11256883 | AD7: -0.051677138 | AE7: -0.17269845 | AF7: -0.070970947 | AG7: 9.2746146e-07 | AH7: 0.22096493 | AI7: 0.1115387 | AJ7: 0.17531252 | AK7: 0.062652189 | AL7: -0.086757277 | AM7: 0.19769117 | AN7: 0.077504791 | AO7: 0.0030230158 | AP7: 0.049361633 | AQ7: 0.031906971 | AR7: -0.014773326 | AS7: 0.097890584 | AT7: 0.078347206 | AU7: 0.18437639 | AV7: 0.28592331 | AW7: -0.15541705 | AX7: 0.20525173 | AY7: -0.19542858 | AZ7: 0.063360502 | BA7: -0.070789821 | BB7: 0.1922658 | BC7: -0.046226905 | BD7: 0.11683152 | BE7: 0.084100627 | BF7: -0.015449154 | BG7: 0.017736926 | BH7: -0.15911203 | BI7: 0.21448514 | BJ7: 0.13602607 | BK7: 0.043799848 | BL7: 0.044637468 | BM7: 0.015490911 | BN7: 0.079273161 | BO7: -0.23406177 | BP7: -0.0056709726 | BQ7: -0.00080271152 | BR7: 0.0058775004 | BS7: 5.1720469e-05 | BT7: -0.02335106 | BU7: -0.045108296 | BV7: 0.1746235 | BW7: 0.18318336 | BX7: -0.057343485 | BY7: 0.0018721562 | BZ7: -0.22738944 | CA7: -0.019112354 | CB7: 0.0066793397 | CC7: -0.0014612681 | CD7: -0.015385947 | CE7: -0.16360229 | CF7: 0.065536527 | CG7: -0.11468922 | CH7: -0.034380161 | CI7: -3.192523e-08 | CJ7: -0.082502689 | CK7: -0.026732885 | CL7: 0.074739522 | CM7: -0.063597958 | CN7: -0.058387016 | CO7: -0.11846439 | CP7: -0.058285747 | CQ7: -0.22391517 | CR7: -0.088506016 | CS7: -0.19027722 | CT7: 0.15782718 | CU7: -0.10178645 | CV7: -0.033652439
A9: b1 (n_hidden1)
A10: -0.13104585 | B10: -0.17766648 | C10: 0.1549345 | D10: -0.20049374 | E10: 0.018885778 | F10: 0.0091665059 | G10: 0.24117073 | H10: 0.135486 | I10: 0.0071522447 | J10: 0.24360796 | K10: 0.056236461 | L10: -0.20938793 | M10: 0.046139541 | N10: -0.18273428 | O10: 0.14976447 | P10: 0.18860895 | Q10: 0.0069465807 | R10: -0.074790773 | S10: 0.044367301 | T10: -0.015351181 | U10: -0.040563748 | V10: -0.0030075909 | W10: 0.11294368 | X10: 0.14681702 | Y10: 0.1895831 | Z10: 0.041832299 | AA10: 0.064447689 | AB10: -0.001610598 | AC10: 0.037488229 | AD10: 0.19495272 | AE10: -0.18003814 | AF10: -0.20844205 | AG10: 0.14658607 | AH10: 0.021872891 | AI10: 0.12922648 | AJ10: -0.092111914 | AK10: -0.069349934 | AL10: 0.027741302 | AM10: 0.049519147 | AN10: 0.10572502 | AO10: 0.029317587 | AP10: -0.014094286 | AQ10: -0.099658192 | AR10: -0.085157728 | AS10: 0.20532995 | AT10: 0.12647588 | AU10: -0.072633146 | AV10: 0.16339288 | AW10: 0.11674188 | AX10: 0.012107675 | AY10: 0.19508473 | AZ10: -0.206325 | BA10: 0.083144992 | BB10: -0.1939078 | BC10: 0.056005316 | BD10: -0.022820233 | BE10: -0.10313371 | BF10: 0.039314217 | BG10: -0.038112108 | BH10: 0.20808095 | BI10: 0.12437915 | BJ10: -0.21054991 | BK10: -0.098602797 | BL10: 0.10682683 | BM10: 0.18140327 | BN10: -0.016253191 | BO10: -0.040273058 | BP10: 0.091878118 | BQ10: 0.075628217 | BR10: -0.21559623 | BS10: 0.15119574 | BT10: -0.10544487 | BU10: -0.022255454 | BV10: 0.23017164 | BW10: 0.14877959 | BX10: -0.15374673 | BY10: 0.13691051 | BZ10: 0.15654367 | CA10: 0.06778944 | CB10: 0.21405378 | CC10: 0.051224902 | CD10: 0.010672902 | CE10: 0.19804973 | CF10: 0.10987468 | CG10: 0.2352309 | CH10: -0.14601593 | CI10: 0.13300065 | CJ10: 0.047019124 | CK10: -0.095532877 | CL10: 0.04757247 | CM10: 0.20024765 | CN10: -0.0026566371 | CO10: -0.075193229 | CP10: -0.1253709 | CQ10: -0.13135194 | CR10: -0.21554719 | CS10: -0.16348061 | CT10: -0.16682327 | CU10: -0.015750286 | CV10: 0.1066506
A12: W2 (n_hidden1 x n_hidden2)
A13: -0.035018804 | B13: -3.0545598e-05 | C13: 0.15734494 | D13: -0.00018250355 | E13: 0.00042811888 | F13: -1.0841585e-06 | G13: 0.070885986 | H13: 0.038323135 | I13: 0.13906458 | J13: 0.12939032 | K13: -0.0013228092 | L13: -0.037943848 | M13: 0.0028750629 | N13: -0.15986111 | O13: 0.028224007 | P13: 0.14224952 | Q13: 0.10949788 | R13: 0.014501932 | S13: 0.090687458 | T13: -0.075088612 | U13: -0.1022622 | V13: 0.13978689 | W13: -0.13938039 | X13: 0.16040226 | Y13: 0.034703277 | Z13: 0.15144558 | AA13: -0.0054115952 | AB13: -0.02628406 | AC13: 0.0055216586 | AD13: 0.030605833 | AE13: -0.032623556 | AF13: 0.097082569 | AG13: 0.055369283 | AH13: -0.0024102847 | AI13: 0.00013517932 | AJ13: 0.15296082 | AK13: -0.00096889791 | AL13: -0.056402238 | AM13: 0.068522281 | AN13: -0.13285241 | AO13: 0.017138892 | AP13: 0.12106755 | AQ13: -0.035678767 | AR13: 0.00014666989 | AS13: 0.031920354 | AT13: 0.0042144004 | AU13: -0.00081947238 | AV13: 0.063643862 | AW13: -0.11501821 | AX13: -0.083343898 | AY13: 5.0434637e-07 | AZ13: 0.10296877 | BA13: 0.010260487 | BB13: 0.0055333963 | BC13: 0.10498901 | BD13: 0.038575312 | BE13: 0.0053716512 | BF13: 0.06008398 | BG13: 0.018654285 | BH13: -0.026209933 | BI13: 0.066326438 | BJ13: -0.018949373 | BK13: 0.0023229196 | BL13: 0.019197396 | BM13: 0.14219052 | BN13: 0.045938472 | BO13: 0.072607784 | BP13: -0.0013497728 | BQ13: -0.065502743 | BR13: 0.081570393 | BS13: -0.0079084826 | BT13: 0.11068241 | BU13: -0.0024485839 | BV13: -0.00069688672 | BW13: 0.061457888 | BX13: 0.034591087 | BY13: 0.11095582 | BZ13: -0.02727468 | CA13: 0.036338401 | CB13: 0.017922697 | CC13: -0.041053223 | CD13: 0.11012137 | CE13: -0.082895869 | CF13: 0.13855084 | CG13: 0.14165674 | CH13: -0.11200436 | CI13: -0.014821444 | CJ13: 0.026934952 | CK13: -0.14404479 | CL13: 1.4197033e-05 | CM13: -0.0014810588 | CN13: 0.088879 | CO13: 0.016928332 | CP13: -0.17264288 | CQ13: 0.0095312374 | CR13: 0.13728575 | CS13: 0.00058973396 | CT13: 0.024608905 | CU13: -0.033320012 | CV13: -0.076555588
A14: 3.0029393e-06 | B14: 0.13153367 | C14: 0.073166704 | D14: -0.033748669 | E14: -0.035023367 | F14: 0.031711143 | G14: -0.10661056 | H14: 0.004037507 | I14: -0.17370056 | J14: -0.080255106 | K14: 7.1349333e-07 | L14: -1.0713437e-07 | M14: 0.17051038 | N14: 0.14818653 | O14: -0.052214554 | P14: -0.0095309886 | Q14: -0.086105855 | R14: 0.023553626 | S14: 0.0089543999 | T14: 0.12807739 | U14: -0.028268159 | V14: 0.0089059036 | W14: 0.13583756 | X14: 0.15435702 | Y14: -0.15407935 | Z14: 0.12122537 | AA14: -0.03540966 | AB14: -0.1742194 | AC14: 0.031362807 | AD14: -0.10547883 | AE14: -0.16528528 | AF14: 0.083773969 | AG14: -0.15336815 | AH14: -8.6409126e-05 | AI14: 0.0023665528 | AJ14: -0.00066480694 | AK14: 1.2792344e-06 | AL14: 0.02140595 | AM14: 0.027107673 | AN14: -0.091281455 | AO14: -0.14652647 | AP14: 0.016736088 | AQ14: -0.15041357 | AR14: -0.11845246 | AS14: -0.011357652 | AT14: 0.066921027 | AU14: 0.086696577 | AV14: -0.048984428 | AW14: 0.067805709 | AX14: 0.023652205 | AY14: -0.11486581 | AZ14: -0.17449532 | BA14: 0.093343708 | BB14: -0.015626638 | BC14: -0.085447024 | BD14: -0.09989336 | BE14: 0.13248901 | BF14: 0.16431225 | BG14: -0.0015222086 | BH14: -0.02142492 | BI14: -0.16741063 | BJ14: -0.15291414 | BK14: -0.0237698 | BL14: 0.094602585 | BM14: 0.015190196 | BN14: 0.13280618 | BO14: 0.096946808 | BP14: 0.098658527 | BQ14: -0.053127867 | BR14: -0.044459779 | BS14: -0.010061733 | BT14: 0.010374193 | BU14: -2.7855113e-08 | BV14: 0.033022595 | BW14: 0.018435172 | BX14: 0.046875107 | BY14: -0.010837694 | BZ14: 0.028494569 | CA14: 7.59296e-05 | CB14: -0.02225967 | CC14: -0.0097607725 | CD14: 0.12264304 | CE14: 0.017371431 | CF14: -0.10200785 | CG14: 0.078988181 | CH14: -0.094379538 | CI14: -0.02930875 | CJ14: -0.1068723 | CK14: -0.048210237 | CL14: -0.010094169 | CM14: -0.1305187 | CN14: 0.056938354 | CO14: 0.034010455 | CP14: 0.010735201 | CQ14: 0.16699156 | CR14: 0.13031735 | CS14: -0.003105833 | CT14: 0.0075941449 | CU14: -2.8474816e-05 | CV14: 0.11101746
A15: -0.0001422284 | B15: -0.10212369 | C15: 0.12101839 | D15: -0.038973446 | E15: -0.0015719191 | F15: -0.14351023 | G15: -0.035361534 | H15: -0.03581733 | I15: -0.11424972 | J15: 0.162535 | K15: -0.0045573203 | L15: -0.016441754 | M15: -0.08792013 | N15: -0.14726031 | O15: 0.074395577 | P15: -0.092904177 | Q15: -0.08850698 | R15: 0.073471462 | S15: 0.0018228138 | T15: -0.085904757 | U15: 0.057122664 | V15: -0.11461936 | W15: 0.037916784 | X15: -0.16088704 | Y15: 0.0096949356 | Z15: -0.086236082 | AA15: -0.15529385 | AB15: 0.14012154 | AC15: -0.032836503 | AD15: 0.021316351 | AE15: 0.035046332 | AF15: 0.10589952 | AG15: -0.058415341 | AH15: -0.031548014 | AI15: -2.9847702e-05 | AJ15: 0.0078099943 | AK15: 0.00820142 | AL15: -0.090309893 | AM15: -0.05330278 | AN15: -0.084746112 | AO15: 0.0042857514 | AP15: 0.077215082 | AQ15: -0.033490983 | AR15: 0.14324399 | AS15: -0.034847137 | AT15: -0.12316496 | AU15: 0.056534256 | AV15: -0.057881994 | AW15: -0.14166688 | AX15: -0.08271408 | AY15: 0.16294109 | AZ15: 0.12715048 | BA15: 0.086436738 | BB15: 0.10654314 | BC15: 0.1076641 | BD15: -0.069959946 | BE15: 0.082785737 | BF15: -0.051613336 | BG15: -0.011126147 | BH15: 0.010026724 | BI15: 0.03044814 | BJ15: -0.073241077 | BK15: 0.00079637458 | BL15: 0.0084293352 | BM15: 0.11874913 | BN15: 0.037904403 | BO15: 0.096560223 | BP15: -0.076455271 | BQ15: 0.14372703 | BR15: -0.087199153 | BS15: -0.017237473 | BT15: -0.1600479 | BU15: -0.020685448 | BV15: 0.07792057 | BW15: -0.091196132 | BX15: 0.0091965735 | BY15: -0.16715767 | BZ15: 0.026296191 | CA15: -0.042017966 | CB15: -0.023773171 | CC15: -0.0048904558 | CD15: 0.12062777 | CE15: -0.06990158 | CF15: -0.045871201 | CG15: 0.024406754 | CH15: -0.090850454 | CI15: -0.06710702 | CJ15: -0.10323887 | CK15: -0.10492632 | CL15: -0.0073173498 | CM15: 0.044634711 | CN15: 0.14224235 | CO15: -0.0011234301 | CP15: 0.13764853 | CQ15: -0.11940641 | CR15: 0.067281212 | CS15: 0.040049921 | CT15: -0.011278039 | CU15: -0.020016641 | CV15: -0.087295737
A16: 0.029467604 | B16: 0.0021688136 | C16: -0.01697817 | D16: 0.037207814 | E16: -0.024483635 | F16: -0.035991243 | G16: -0.017490576 | H16: 1.2275117e-06 | I16: 0.027204322 | J16: 0.00011510793 | K16: 0.0010918959 | L16: 0.016535494 | M16: -7.2624574e-06 | N16: 0.0013603102 | O16: 0.021852998 | P16: 0.0040006289 | Q16: -0.00058238202 | R16: 0.027117067 | S16: -0.011914842 | T16: 1.4960161e-05 | U16: 0.00019597052 | V16: -0.0088007227 | W16: -0.019399443 | X16: 0.0097362252 | Y16: 0.0022234782 | Z16: 0.00048233724 | AA16: 0.010887662 | AB16: 3.0331929e-06 | AC16: -1.3089563e-06 | AD16: -4.5269395e-05 | AE16: -0.031156386 | AF16: 1.2782519e-06 | AG16: 0.0036604062 | AH16: -0.010264449 | AI16: 0.010885089 | AJ16: 0.011833972 | AK16: -0.010679469 | AL16: -0.040385145 | AM16: 0.0077849743 | AN16: -2.9747009e-08 | AO16: -0.0036073745 | AP16: -0.040117229 | AQ16: -0.031638145 | AR16: 0.0064589703 | AS16: 0.00020037253 | AT16: 1.2660241e-06 | AU16: 5.4928597e-13 | AV16: 0.036669939 | AW16: 2.6762795e-08 | AX16: 0.0010517004 | AY16: 5.2597749e-06 | AZ16: -8.7989522e-06 | BA16: 3.1821204e-05 | BB16: -0.011939639 | BC16: -0.0038447184 | BD16: -0.025609362 | BE16: -0.012920526 | BF16: -0.03724281 | BG16: 0.029566142 | BH16: 7.9672386e-06 | BI16: 0.00023102133 | BJ16: 0.010260334 | BK16: -0.011452961 | BL16: -0.0037746926 | BM16: -0.0084548966 | BN16: 7.8309963e-07 | BO16: -0.041970599 | BP16: 0.0021514805 | BQ16: 1.9704816e-05 | BR16: -0.0033103022 | BS16: 0.0025957598 | BT16: -0.037870856 | BU16: 1.0950476e-08 | BV16: -5.7327137e-05 | BW16: -0.0021752575 | BX16: -0.013000383 | BY16: 0.0010065522 | BZ16: 0.02305537 | CA16: -0.0010608416 | CB16: 2.9010664e-05 | CC16: -7.5284733e-07 | CD16: 0.034543609 | CE16: 0.015692383 | CF16: -7.486665e-07 | CG16: 1.0774753e-06 | CH16: 0.0037945048 | CI16: 0.039519521 | CJ16: 0.009486961 | CK16: -0.02009961 | CL16: 0.0068824252 | CM16: -0.018653042 | CN16: -0.04177775 | CO16: 0.019764763 | CP16: 0.018561407 | CQ16: -0.0099192413 | CR16: 0.027542479 | CS16: -0.03327777 | CT16: -0.0089616026 | CU16: -0.00064696904 | CV16: -0.019994222
A17: -1.1054761e-06 | B17: -0.040372842 | C17: 0.14723625 | D17: 0.011520265 | E17: 0.0027273906 | F17: 0.089580236 | G17: -0.069862079 | H17: -0.016515763 | I17: 0.1152266 | J17: -0.11956628 | K17: 8.7996478e-07 | L17: -0.0023192909 | M17: -0.17846224 | N17: 0.16118342 | O17: 0.062920322 | P17: -0.16211152 | Q17: -0.12229076 | R17: 0.14493635 | S17: -0.025412814 | T17: -0.051035992 | U17: 0.086876176 | V17: 0.13627767 | W17: -0.15089917 | X17: -0.017491159 | Y17: 0.035673301 | Z17: -0.050831815 | AA17: 0.029543294 | AB17: -0.095579407 | AC17: -0.0090363852 | AD17: -0.034781795 | AE17: 0.15101186 | AF17: 0.039193024 | AG17: 0.27658865 | AH17: 0.029916254 | AI17: 0.031374621 | AJ17: 0.11074512 | AK17: 0.00011643431 | AL17: -0.012284321 | AM17: 0.050863181 | AN17: -0.03655164 | AO17: 0.042318389 | AP17: -0.13759921 | AQ17: 0.13992482 | AR17: 0.040079337 | AS17: 0.057326252 | AT17: -0.0017952186 | AU17: 0.12648737 | AV17: 0.086427903 | AW17: 0.15165649 | AX17: -0.053185556 | AY17: 3.2191797e-08 | AZ17: 0.064330983 | BA17: 0.069341095 | BB17: -0.10011498 | BC17: -0.13539854 | BD17: 0.1517339 | BE17: 0.0017956188 | BF17: 0.025947691 | BG17: 0.0002102301 | BH17: 8.3410589e-05 | BI17: -0.10628421 | BJ17: 0.057228131 | BK17: 0.030469647 | BL17: 0.17512782 | BM17: -0.07153454 | BN17: 0.14730287 | BO17: 0.15070074 | BP17: 0.13763599 | BQ17: 0.12288212 | BR17: 0.080190619 | BS17: 0.031206752 | BT17: -0.066664653 | BU17: -0.037626078 | BV17: -0.14130282 | BW17: -0.083808671 | BX17: -0.087975694 | BY17: -0.0085338617 | BZ17: 0.16280264 | CA17: -0.01209498 | CB17: 0.00084617677 | CC17: -3.2334701e-05 | CD17: 0.11832305 | CE17: -0.016827808 | CF17: -0.15650007 | CG17: -0.0808398 | CH17: 0.14787893 | CI17: -0.113618 | CJ17: 5.7874581e-06 | CK17: 0.021178484 | CL17: 0.07652526 | CM17: 0.014661289 | CN17: 0.044903462 | CO17: 0.01427961 | CP17: 0.044344937 | CQ17: 0.033895598 | CR17: -0.17767562 | CS17: 0.091184202 | CT17: 0.00044216664 | CU17: 0.039264571 | CV17: 0.026420668
A18: 0.0002799479 | B18: -0.00048703236 | C18: 0.0046666196 | D18: -0.00099588315 | E18: 0.01940959 | F18: 1.1292221e-06 | G18: -9.4751968e-06 | H18: -0.0053513037 | I18: 0.036341117 | J18: -0.013172663 | K18: 0.01051066 | L18: -0.0029985153 | M18: -0.0014264709 | N18: 0.000166389 | O18: -0.00024533675 | P18: 0.016647275 | Q18: 0.0061037155 | R18: -0.00087985836 | S18: 4.7128645e-06 | T18: -0.034637709 | U18: 8.1732767e-05 | V18: -0.025327934 | W18: 0.00030469319 | X18: 0.0062991068 | Y18: 0.005536854 | Z18: -0.035245265 | AA18: -0.037888454 | AB18: 0.0042252767 | AC18: -0.021666013 | AD18: -0.00082668575 | AE18: -0.00069796324 | AF18: 2.3661621e-06 | AG18: -0.038292914 | AH18: 0.0001244375 | AI18: 0.039760831 | AJ18: -0.00073572084 | AK18: 2.722708e-05 | AL18: -7.0018958e-05 | AM18: -0.00013323629 | AN18: -1.7300872e-07 | AO18: -0.031572489 | AP18: 0.0053499628 | AQ18: 0.013705457 | AR18: 0.017162258 | AS18: -0.002555956 | AT18: 0.014001972 | AU18: 0.0086281475 | AV18: 0.0045986924 | AW18: -0.0023850635 | AX18: -0.00052705494 | AY18: 1.1932635e-06 | AZ18: 0.00057078563 | BA18: 0.0052406438 | BB18: -0.030058071 | BC18: 1.3255235e-05 | BD18: 0.029298081 | BE18: 0.00072695751 | BF18: 0.00054821395 | BG18: -0.030992413 | BH18: -2.0673505e-07 | BI18: 0.0053747082 | BJ18: -1.4451031e-07 | BK18: 2.1009353e-08 | BL18: -0.00010453447 | BM18: -0.041199428 | BN18: -2.2690508e-08 | BO18: 2.9152568e-05 | BP18: 0.005976813 | BQ18: -1.7873621e-05 | BR18: 0.0047780287 | BS18: 0.02117259 | BT18: 0.0065532706 | BU18: 0.0046827015 | BV18: 0.002386738 | BW18: -0.028890943 | BX18: -0.0068374871 | BY18: 2.975017e-05 | BZ18: 0.03747356 | CA18: 0.019930765 | CB18: 0.033206561 | CC18: -0.002586601 | CD18: 1.1935489e-07 | CE18: -0.020883053 | CF18: 4.873586e-07 | CG18: 0.00025216622 | CH18: 0.0024051513 | CI18: -8.8913337e-08 | CJ18: -0.0012067966 | CK18: -0.023604799 | CL18: 0.012638803 | CM18: -0.0062442019 | CN18: 0.01027812 | CO18: 0.009296888 | CP18: -0.00045444512 | CQ18: -1.0642555e-06 | CR18: 0.0036341893 | CS18: 6.2954609e-07 | CT18: 4.7862468e-07 | CU18: 0.026966959 | CV18: 0.0050579304
A19: 0.035904136 | B19: -0.12598736 | C19: -0.00489519 | D19: -0.0054501053 | E19: 0.018299764 | F19: 0.011659772 | G19: 0.13867642 | H19: -0.036667877 | I19: -0.17437072 | J19: -0.12174636 | K19: 3.0639623e-07 | L19: -0.031134832 | M19: 0.15307844 | N19: 0.096945951 | O19: -0.0046348189 | P19: -0.093131247 | Q19: -0.020675496 | R19: -0.097163443 | S19: -0.031447654 | T19: -0.10551968 | U19: 0.038098607 | V19: 0.044169797 | W19: -0.10133926 | X19: 0.1573791 | Y19: -0.10253083 | Z19: -0.1029312 | AA19: 0.13557498 | AB19: 0.04390299 | AC19: -0.019540517 | AD19: -0.0063058102 | AE19: -0.10679139 | AF19: -0.055615352 | AG19: 0.096390856 | AH19: 9.6984453e-07 | AI19: -0.024063394 | AJ19: 0.14565214 | AK19: 0.0010755511 | AL19: 0.15036446 | AM19: 0.081441365 | AN19: -0.10170981 | AO19: 0.045313148 | AP19: -0.053146978 | AQ19: -0.046166347 | AR19: 0.030353317 | AS19: -0.0080182516 | AT19: -0.18265689 | AU19: -0.14174431 | AV19: -0.099228267 | AW19: -0.16200886 | AX19: 0.10742765 | AY19: -0.037967582 | AZ19: 0.016853453 | BA19: -0.0060453466 | BB19: -0.11130481 | BC19: 0.16380332 | BD19: -0.030826991 | BE19: 0.044683012 | BF19: 0.095316448 | BG19: 0.04020523 | BH19: -1.7340805e-07 | BI19: 0.17890324 | BJ19: -0.096033378 | BK19: 0.015610685 | BL19: 0.12618722 | BM19: -0.098788963 | BN19: -0.16330083 | BO19: 0.14757814 | BP19: 0.16605199 | BQ19: -0.068589619 | BR19: 0.038218709 | BS19: -0.0062985754 | BT19: -0.038252759 | BU19: 0.0055217098 | BV19: 0.17457268 | BW19: -0.18254667 | BX19: -0.019294137 | BY19: 0.085923721 | BZ19: 0.038424452 | CA19: -0.0027629626 | CB19: 0.002759246 | CC19: 0.014224849 | CD19: -0.14064024 | CE19: 0.059570802 | CF19: -0.0054930555 | CG19: -0.14367978 | CH19: 3.3413219e-05 | CI19: -0.10749552 | CJ19: -0.0997848 | CK19: -0.15559802 | CL19: -0.0089773287 | CM19: 0.15167424 | CN19: -0.016316405 | CO19: -0.023755881 | CP19: 0.16106096 | CQ19: -0.059011037 | CR19: -0.073766872 | CS19: -0.086140687 | CT19: 0.022485856 | CU19: -2.171161e-05 | CV19: 0.008057943
A20: 0.0026776468 | B20: -0.0010969735 | C20: -0.14967469 | D20: -0.018347215 | E20: -0.022842531 | F20: -0.019437079 | G20: -0.046922098 | H20: 0.011537174 | I20: -0.081008378 | J20: 0.0091309404 | K20: -0.04168472 | L20: -0.0013056499 | M20: -0.03351863 | N20: 0.1408287 | O20: 0.052945178 | P20: -0.016526968 | Q20: -0.12096604 | R20: 0.02346711 | S20: 0.014790183 | T20: -0.059601439 | U20: 0.068481885 | V20: -0.078302019 | W20: -0.096226115 | X20: -0.086010085 | Y20: -0.074938014 | Z20: -0.045877913 | AA20: 0.072665333 | AB20: 0.11475623 | AC20: 0.0013640906 | AD20: -0.053807489 | AE20: -0.040678082 | AF20: 0.064757169 | AG20: -0.1232828 | AH20: 0.0024447792 | AI20: 0.037174153 | AJ20: 0.10121473 | AK20: 2.1410565e-06 | AL20: -0.027369867 | AM20: 0.21696683 | AN20: 0.03478052 | AO20: -0.10855643 | AP20: -0.085507557 | AQ20: -0.18707264 | AR20: 0.10471433 | AS20: -0.0071414263 | AT20: 0.039176626 | AU20: 0.13976696 | AV20: -0.15955803 | AW20: -0.03232041 | AX20: 0.05727637 | AY20: -1.2473196e-06 | AZ20: 0.15803982 | BA20: -0.097329386 | BB20: 0.26023208 | BC20: -0.034550867 | BD20: 0.064749248 | BE20: 0.13073586 | BF20: -0.149199 | BG20: 0.020773356 | BH20: 0.032191859 | BI20: 0.018389514 | BJ20: -0.12939301 | BK20: -5.2410319e-06 | BL20: -0.065416491 | BM20: 0.19041825 | BN20: 0.027769313 | BO20: 0.03475933 | BP20: -0.05173789 | BQ20: -0.041807834 | BR20: -0.034481594 | BS20: -0.030307998 | BT20: 0.2238602 | BU20: 0.0030791761 | BV20: 0.11145718 | BW20: 0.033096115 | BX20: 0.068128361 | BY20: 0.10316572 | BZ20: 0.11010171 | CA20: -0.00011319652 | CB20: 1.4669919e-07 | CC20: 0.032641577 | CD20: 0.12420895 | CE20: 0.019233566 | CF20: -0.15075584 | CG20: -0.11143617 | CH20: -0.12223534 | CI20: -5.820485e-05 | CJ20: -0.048977452 | CK20: 0.14751985 | CL20: -0.018720879 | CM20: -0.10441185 | CN20: 0.17915058 | CO20: -0.0019988391 | CP20: -0.10011744 | CQ20: -0.037501809 | CR20: -0.14851882 | CS20: -0.0078111637 | CT20: 0.03756399 | CU20: -0.010792739 | CV20: 0.11260172
A21: -0.00014790344 | B21: 0.0032175182 | C21: 0.12624561 | D21: -4.133123e-05 | E21: 0.011716891 | F21: -0.011499636 | G21: 3.0876997e-07 | H21: 0.039798654 | I21: -0.17390719 | J21: -0.15868047 | K21: 0.0004779479 | L21: -0.025094507 | M21: 0.026144091 | N21: 0.054067522 | O21: 0.033121344 | P21: 0.00039443316 | Q21: 0.10065269 | R21: 0.017945812 | S21: 0.014477567 | T21: 0.00015811521 | U21: 0.089636661 | V21: -0.02315463 | W21: 0.015523076 | X21: -0.076875382 | Y21: 0.11496297 | Z21: 0.15085636 | AA21: -0.029024912 | AB21: -0.012983734 | AC21: 0.033834064 | AD21: -0.077060267 | AE21: 0.11589083 | AF21: -0.019536871 | AG21: -0.049910713 | AH21: -0.022433624 | AI21: 0.03750266 | AJ21: 0.007092634 | AK21: 0.0051446711 | AL21: 0.12688877 | AM21: 0.00089961504 | AN21: 0.029628691 | AO21: -0.16093096 | AP21: 0.15802034 | AQ21: -0.12014335 | AR21: 0.046319443 | AS21: 0.0023046415 | AT21: -0.0036025343 | AU21: 0.00048361254 | AV21: 0.052174019 | AW21: -0.021380398 | AX21: -0.030292637 | AY21: -0.0013937985 | AZ21: 0.03750503 | BA21: -0.039071807 | BB21: 0.035403022 | BC21: -0.011310711 | BD21: 0.18163278 | BE21: 0.12559883 | BF21: 0.013169421 | BG21: -0.0016473386 | BH21: 0.010513806 | BI21: 0.13161163 | BJ21: 0.032462955 | BK21: -3.085728e-08 | BL21: 0.14596007 | BM21: 0.057338593 | BN21: 0.0017391538 | BO21: 0.13821262 | BP21: 0.13998364 | BQ21: 0.18234104 | BR21: -0.15540556 | BS21: 0.0090815978 | BT21: -0.17582155 | BU21: -0.034687267 | BV21: -0.0049354298 | BW21: 0.030223936 | BX21: 0.162453 | BY21: -0.021769277 | BZ21: -0.17748594 | CA21: 0.0060268595 | CB21: 0.01202565 | CC21: 5.4181009e-07 | CD21: -0.01715876 | CE21: 0.072242874 | CF21: 0.14121052 | CG21: 0.064580367 | CH21: -0.076291555 | CI21: -0.002232183 | CJ21: -0.017163984 | CK21: -0.0012401514 | CL21: -0.034395194 | CM21: 0.014747789 | CN21: 0.15192795 | CO21: 5.6438231e-09 | CP21: 0.047347228 | CQ21: -0.0055942246 | CR21: 0.03438087 | CS21: 0.011723606 | CT21: 0.012747175 | CU21: -0.0037012142 | CV21: -0.041820689
A22: -0.0074056475 | B22: -0.0786666 | C22: 0.1307886 | D22: 0.074104981 | E22: 0.014201643 | F22: 0.085180977 | G22: -0.12611158 | H22: -2.9473133e-08 | I22: -0.007935116 | J22: 0.021923854 | K22: -0.028297896 | L22: 0.014810907 | M22: 0.075848308 | N22: -0.077491186 | O22: 0.12887667 | P22: 0.13399248 | Q22: -0.13386065 | R22: 0.073188236 | S22: -0.15346213 | T22: 0.1543772 | U22: 0.14495517 | V22: -0.060932021 | W22: -0.067967947 | X22: 0.1197943 | Y22: 0.15372166 | Z22: -0.0011050766 | AA22: -0.17010302 | AB22: 0.10076534 | AC22: -0.01292077 | AD22: -0.091551573 | AE22: -0.13115772 | AF22: -0.0085472154 | AG22: 0.058016328 | AH22: 0.00056497455 | AI22: -1.530529e-07 | AJ22: 0.047497742 | AK22: -5.9342201e-07 | AL22: -0.10686342 | AM22: 0.1233353 | AN22: 0.037103435 | AO22: -0.042698493 | AP22: -0.17315677 | AQ22: -0.17041359 | AR22: -0.014502065 | AS22: -0.0051057106 | AT22: -0.085197935 | AU22: 0.0064296879 | AV22: 0.016161161 | AW22: 0.034610005 | AX22: 0.12606087 | AY22: -0.022513735 | AZ22: 0.048444589 | BA22: 0.047211557 | BB22: 0.078250446 | BC22: 0.080294949 | BD22: -0.080573503 | BE22: 0.10965826 | BF22: 0.030829802 | BG22: -0.037978251 | BH22: 0.0016173805 | BI22: -0.074330321 | BJ22: 0.037042244 | BK22: 0.0033148881 | BL22: 0.0032858997 | BM22: 0.078605617 | BN22: -0.019046462 | BO22: -0.037955181 | BP22: 0.095117125 | BQ22: -0.12392769 | BR22: -0.11269986 | BS22: 1.1224487e-06 | BT22: 0.15049268 | BU22: 0.00041691151 | BV22: 0.086819034 | BW22: 0.067697643 | BX22: 0.056461333 | BY22: 0.080331677 | BZ22: 0.1132632 | CA22: -0.031788674 | CB22: -4.6099087e-08 | CC22: 0.0030162566 | CD22: 0.063686746 | CE22: -0.12542233 | CF22: -0.15701463 | CG22: -0.039200901 | CH22: 0.11807459 | CI22: 0.01333387 | CJ22: -0.1586533 | CK22: 0.09448631 | CL22: 0.022121579 | CM22: -0.15133587 | CN22: 0.022531286 | CO22: -0.006796736 | CP22: -0.068798423 | CQ22: -0.12967211 | CR22: 0.077865011 | CS22: -0.012904902 | CT22: 0.031467454 | CU22: 6.0346082e-07 | CV22: 0.017678719
A23: -0.028501837 | B23: 1.8706748e-05 | C23: -0.041165653 | D23: -3.5172117e-08 | E23: 0.038320722 | F23: -1.1713342e-06 | G23: -0.041394195 | H23: 0.0003796646 | I23: -0.02499338 | J23: 1.0904729e-06 | K23: -0.02102665 | L23: -0.00010983434 | M23: 0.034339582 | N23: 0.00072471061 | O23: -0.022235919 | P23: 0.041163614 | Q23: 9.4461837e-08 | R23: -0.0025361782 | S23: -8.2674795e-07 | T23: -0.013600039 | U23: -0.021849212 | V23: 0.00082511017 | W23: -8.4559137e-07 | X23: 0.024594723 | Y23: 0.0021297385 | Z23: 0.00033305438 | AA23: -0.0019577152 | AB23: 0.041166676 | AC23: -0.0093159248 | AD23: 0.00043017004 | AE23: 0.029255824 | AF23: -3.0452069e-08 | AG23: -1.2637151e-06 | AH23: -6.1883618e-06 | AI23: 7.1135751e-07 | AJ23: -0.0049489792 | AK23: 0.030105694 | AL23: 1.9696286e-05 | AM23: -0.01806485 | AN23: -0.0044592443 | AO23: -2.7672554e-08 | AP23: -0.030305681 | AQ23: 9.0387444e-07 | AR23: -0.0006992564 | AS23: -0.00028532459 | AT23: -0.00075859417 | AU23: 1.2787821e-06 | AV23: -7.7904578e-05 | AW23: 0.0072598217 | AX23: -6.9804118e-05 | AY23: -0.00013795886 | AZ23: 2.6706455e-05 | BA23: 0.0041213944 | BB23: 0.035407161 | BC23: 0.009063775 | BD23: 1.1346961e-06 | BE23: 1.8030437e-07 | BF23: -0.0035273819 | BG23: 0.038577441 | BH23: -0.035474144 | BI23: 0.01440413 | BJ23: -0.012102003 | BK23: 0.023428549 | BL23: 1.9653967e-05 | BM23: -0.016322646 | BN23: 0.0020757738 | BO23: -0.01485062 | BP23: -0.010642988 | BQ23: -0.036137048 | BR23: 0.0019014057 | BS23: 0.025690427 | BT23: 0.00077060224 | BU23: 0.002062172 | BV23: 0.0033933417 | BW23: 0.024347933 | BX23: 0.032688725 | BY23: -0.035574897 | BZ23: 4.6636068e-05 | CA23: 0.00069219413 | CB23: 0.004594046 | CC23: -6.7486161e-08 | CD23: -0.027997063 | CE23: -0.023064884 | CF23: 0.034203976 | CG23: -0.016833919 | CH23: -0.002494255 | CI23: 0.035491748 | CJ23: 0.0072131796 | CK23: 0.00039584036 | CL23: -4.3450025e-05 | CM23: 0.034400862 | CN23: -0.0014887245 | CO23: 1.0689693e-06 | CP23: -3.7932647e-05 | CQ23: 6.3685736e-07 | CR23: -4.5956642e-06 | CS23: 0.0065107872 | CT23: 2.4016006e-08 | CU23: -0.0026139081 | CV23: -0.032308605
A24: -0.03365996 | B24: 0.0072107056 | C24: 0.013987317 | D24: -0.03872631 | E24: 0.0049722158 | F24: -0.09762764 | G24: -0.10104894 | H24: -0.025045619 | I24: -0.025177133 | J24: 0.075399351 | K24: -0.0014785651 | L24: 3.5203422e-08 | M24: 0.086896275 | N24: 0.12305922 | O24: -0.019062026 | P24: -2.9258254e-07 | Q24: -0.16764914 | R24: 4.1511526e-07 | S24: -0.082286712 | T24: 0.016183061 | U24: -0.011978236 | V24: -0.12677944 | W24: -0.068080939 | X24: 0.046717781 | Y24: 0.036508864 | Z24: 0.16960737 | AA24: -0.042441447 | AB24: 0.025470545 | AC24: -0.00014447417 | AD24: 0.019386934 | AE24: -0.16412666 | AF24: 0.15713427 | AG24: -0.022940992 | AH24: -0.032323502 | AI24: -0.00039954379 | AJ24: 0.091646204 | AK24: 9.0316835e-05 | AL24: 0.023341013 | AM24: 0.0015000618 | AN24: 0.035641007 | AO24: 0.010484644 | AP24: 0.007188288 | AQ24: 0.013620504 | AR24: 0.096857835 | AS24: 0.013179572 | AT24: -0.077895388 | AU24: 0.13316558 | AV24: -0.076164189 | AW24: -0.15849696 | AX24: -0.064584147 | AY24: 0.012272236 | AZ24: -0.0093455462 | BA24: -0.13227617 | BB24: -0.067215898 | BC24: 0.094808856 | BD24: -0.081084641 | BE24: 0.12864388 | BF24: -0.087413178 | BG24: 0.011453329 | BH24: 0.00023827674 | BI24: 0.083531611 | BJ24: -0.12713963 | BK24: -0.013675716 | BL24: -0.11169798 | BM24: -0.14603638 | BN24: 0.025679651 | BO24: 0.099104011 | BP24: -0.13598875 | BQ24: -0.12245255 | BR24: -0.17921946 | BS24: -3.5149163e-07 | BT24: -0.14974749 | BU24: -0.0012797478 | BV24: -0.015478656 | BW24: 0.18340582 | BX24: -0.040412428 | BY24: 0.030878948 | BZ24: 0.10283448 | CA24: -0.012343517 | CB24: -0.0055447319 | CC24: 0.0071855289 | CD24: 0.11004633 | CE24: 0.14473626 | CF24: 0.02200108 | CG24: 0.019015316 | CH24: 0.026162969 | CI24: -0.025044543 | CJ24: -0.0098530905 | CK24: 0.087041066 | CL24: -4.769174e-05 | CM24: 0.12745598 | CN24: 0.023257122 | CO24: 8.6544585e-05 | CP24: 0.086316399 | CQ24: 0.0094840942 | CR24: -0.16191574 | CS24: 0.037422821 | CT24: 0.00025104987 | CU24: 0.00089263327 | CV24: 0.13471864
... A112: -0.00035616221 | B112: -0.003542243 | C112: -0.0057744195 | D112: 0.02062023 | E112: 0.026325915 | F112: 0.016961058 | G112: 0.013539143 | H112: 4.696297e-08 | I112: -4.6767846e-07 | J112: -0.02836579 | K112: -7.2087179e-05 | L112: -0.029102658 | M112: 0.0079091156 | N112: -0.022936792 | O112: -0.021775033 | P112: -3.1592516e-07 | Q112: 0.00080325446 | R112: 0.033325037 | S112: 0.0018460766 | T112: -1.4057438e-05 | U112: 0.020907621 | V112: -1.1332356e-06 | W112: 0.012981966 | X112: -0.013790454 | Y112: -0.0019935521 | Z112: 0.016874562 | AA112: -1.2620389e-06 | AB112: -3.4222634e-05 | AC112: -0.00013784311 | AD112: 0.0079123422 | AE112: -0.030727322 | AF112: -0.00017195757 | AG112: -0.029878388 | AH112: -0.00013695278 | AI112: -0.00087540526 | AJ112: -0.0017601328 | AK112: 0.030156883 | AL112: -0.032048877 | AM112: 2.7845834e-08 | AN112: -3.1652302e-05 | AO112: 0.021264816 | AP112: -0.0067834467 | AQ112: -0.040777005 | AR112: -0.02145966 | AS112: 5.5362248e-05 | AT112: -0.0054676297 | AU112: -0.00011480191 | AV112: -0.038164558 | AW112: 0.014970518 | AX112: -0.009673215 | AY112: -0.00065445207 | AZ112: 0.0038742059 | BA112: 0.021614245 | BB112: 0.028011063 | BC112: -0.017165276 | BD112: 0.011470083 | BE112: -0.034318138 | BF112: -0.034165013 | BG112: -2.7309284e-05 | BH112: 0.034699669 | BI112: -0.00013358226 | BJ112: -1.2651804e-08 | BK112: 0.020739347 | BL112: -0.0050837697 | BM112: 0.011140838 | BN112: 0.0092848144 | BO112: -0.0046996964 | BP112: -0.01901371 | BQ112: -0.014477267 | BR112: -0.00017584626 | BS112: -0.014881403 | BT112: -0.00047448325 | BU112: 9.0362277e-05 | BV112: -0.018850181 | BW112: 0.02924506 | BX112: -6.0028407e-05 | BY112: -0.009787532 | BZ112: 0.0087328225 | CA112: -0.00040984322 | CB112: 0.028732838 | CC112: 0.019380544 | CD112: 0.0051409178 | CE112: -0.010966318 | CF112: -1.9239476e-08 | CG112: 0.035069272 | CH112: -0.00076069574 | CI112: -0.010417551 | CJ112: -0.026545364 | CK112: -0.0023665661 | CL112: 3.5168029e-08 | CM112: 0.0026988787 | CN112: -0.0076605456 | CO112: -0.0069329741 | CP112: 0.00085880432 | CQ112: -0.0064705168 | CR112: -0.0094142016 | CS112: -0.0010251018 | CT112: -0.00071458924 | CU112: 0.00022954395 | CV112: -0.00065812369
A114: b2 (n_hidden2)
A115: 0.092872781 | B115: 0.020254358 | C115: 0.015090948 | D115: -0.13908299 | E115: -0.015654404 | F115: 0.16573795 | G115: -0.034952307 | H115: -0.11247295 | I115: 0.060656263 | J115: -0.082225383 | K115: 0.13184457 | L115: -0.16549265 | M115: 0.090283123 | N115: 0.14793707 | O115: -0.092314893 | P115: -0.1689357 | Q115: 0.099044049 | R115: -0.057143981 | S115: 0.10429478 | T115: 0.084691873 | U115: 0.17681815 | V115: -0.16844622 | W115: -0.06554621 | X115: -0.12905409 | Y115: -0.13475789 | Z115: 0.15258833 | AA115: 0.15977476 | AB115: 0.16221231 | AC115: 0.11919441 | AD115: -0.070764289 | AE115: 0.07079386 | AF115: 0.15808362 | AG115: -0.074228867 | AH115: -0.11090723 | AI115: 0.05563539 | AJ115: 0.037499072 | AK115: -0.10351976 | AL115: -0.015820945 | AM115: -0.091787393 | AN115: -0.084601242 | AO115: -0.11313358 | AP115: 0.067777458 | AQ115: 0.097932233 | AR115: -0.015050118 | AS115: -0.038897673 | AT115: 0.065932515 | AU115: 0.1659641 | AV115: -0.027594426 | AW115: -0.081788126 | AX115: -0.12428667 | AY115: 0.078300905 | AZ115: -0.14334148 | BA115: 0.031217137 | BB115: 0.043638895 | BC115: -0.12408766 | BD115: 0.15201559 | BE115: -0.005191313 | BF115: 0.085827137 | BG115: -0.082177004 | BH115: 0.1218441 | BI115: -0.16243546 | BJ115: -0.15961224 | BK115: 0.10014412 | BL115: 0.11895591 | BM115: -0.095456021 | BN115: -0.081406162 | BO115: 0.017710843 | BP115: 0.012071181 | BQ115: 0.041054417 | BR115: -0.035554978 | BS115: -0.0051255004 | BT115: 0.051760016 | BU115: -0.1495276 | BV115: -0.0020661188 | BW115: -0.063972118 | BX115: 0.10307855 | BY115: 0.044739263 | BZ115: 0.093011576 | CA115: -0.06225391 | CB115: -0.15523324 | CC115: 0.11240368 | CD115: -0.080977143 | CE115: 0.09524468 | CF115: 0.14157635 | CG115: 0.10661766 | CH115: -0.12758879 | CI115: -0.066193859 | CJ115: 0.026618232 | CK115: -0.089593769 | CL115: 0.070311584 | CM115: 0.15590013 | CN115: -0.081933963 | CO115: -0.058347043 | CP115: -0.048180877 | CQ115: -0.00055035853 | CR115: 0.0063781505 | CS115: 0.012397583 | CT115: -0.10457851 | CU115: 0.031679382 | CV115: -0.10925457
A117: W3 (n_hidden2 x n_classes)
A118: -1.0086075e-06 | B118: 0.046337812 | C118: 0.0082105518
A119: -0.0026792363 | B119: 0.11770628 | C119: -0.10799465
A120: -0.070686026 | B120: -0.14911288 | C120: 0.091213505
A121: 0.12822871 | B121: 0.10048546 | C121: -0.086071396
A122: -0.0030053638 | B122: -0.015200828 | C122: 1.946326e-05
A123: 0.0305465 | B123: 0.064125301 | C123: 0.18139814
A124: -0.1446609 | B124: -0.048940603 | C124: -0.15568345
A125: 0.0015952416 | B125: -0.0011207445 | C125: 0.078964216
A126: -0.16189087 | B126: 0.065776123 | C126: 0.063133771
A127: 0.24273555 | B127: 0.036677699 | C127: -0.01604563
A128: -0.087057417 | B128: 0.023606598 | C128: -0.016906482
A129: -0.079110465 | B129: -0.00048279848 | C129: -6.8155405e-07
... A217: 0.10443402 | B217: 0.17781866 | C217: 0.0090785079
A219: b3 (n_classes)
...

Sheet Inputs
A1: Inferencia MLP (ReLU + Softmax) — Palmer Penguins
A2: Cambia los inputs; la predicción se actualiza al instante.
A4: Inputs crudos
A5: island | B5: culmen_length_mm | C5: culmen_depth_mm | D5: flipper_length_mm | E5: body_mass_g | F5: sex
A6: Biscoe | B6: 39.6 | C6: 18.9 | D6: 187 | E6: 3550 | F6: FEMALE
A8: Inputs codificados (TODAS las columnas fueron LabelEncoded)
A9: island | B9: culmen_length_mm | C9: culmen_depth_mm | D9: flipper_length_mm | E9: body_mass_g | F9: sex
A10: =INDEX(Meta!$B$8:$B$10, MATCH(A6, Meta!$A$8:$A$10, 0)) -> 0 | B10: =INDEX(Meta!$B$14:$B$176, MATCH(B6, Meta!$A$14:$A$176, 0)) -> 45 | C10: =INDEX(Meta!$B$180:$B$258, MATCH(C6, Meta!$A$180:$A$258, 0)) -> 58 | D10: =INDEX(Meta!$B$262:$B$315, MATCH(D6, Meta!$A$262:$A$315, 0)) -> 11 | E10: =INDEX(Meta!$B$319:$B$411, MATCH(E6, Meta!$A$319:$A$411, 0)) -> 22 | F10: =INDEX(Meta!$B$415:$B$416, MATCH(F6, Meta!$A$415:$A$416, 0)) -> 0
A12: Capa 1 — z1; h1=ReLU(z1)
A13: z1_1 | B13: z1_2 | C13: z1_3 | D13: z1_4 | E13: z1_5 | F13: z1_6 | G13: z1_7 | H13: z1_8 | I13: z1_9 | J13: z1_10 | K13: z1_11 | L13: z1_12 | M13: z1_13 | N13: z1_14 | O13: z1_15 | P13: z1_16 | Q13: z1_17 | R13: z1_18 | S13: z1_19 | T13: z1_20 | U13: z1_21 | V13: z1_22 | W13: z1_23 | X13: z1_24 | Y13: z1_25 | Z13: z1_26 | AA13: z1_27 | AB13: z1_28 | AC13: z1_29 | AD13: z1_30 | AE13: z1_31 | AF13: z1_32 | AG13: z1_33 | AH13: z1_34 | AI13: z1_35 | AJ13: z1_36 | AK13: z1_37 | AL13: z1_38 | AM13: z1_39 | AN13: z1_40 | AO13: z1_41 | AP13: z1_42 | AQ13: z1_43 | AR13: z1_44 | AS13: z1_45 | AT13: z1_46 | AU13: z1_47 | AV13: z1_48 | AW13: z1_49 | AX13: z1_50 | AY13: z1_51 | AZ13: z1_52 | BA13: z1_53 | BB13: z1_54 | BC13: z1_55 | BD13: z1_56 | BE13: z1_57 | BF13: z1_58 | BG13: z1_59 | BH13: z1_60 | BI13: z1_61 | BJ13: z1_62 | BK13: z1_63 | BL13: z1_64 | BM13: z1_65 | BN13: z1_66 | BO13: z1_67 | BP13: z1_68 | BQ13: z1_69 | BR13: z1_70 | BS13: z1_71 | BT13: z1_72 | BU13: z1_73 | BV13: z1_74 | BW13: z1_75 | BX13: z1_76 | BY13: z1_77 | BZ13: z1_78 | CA13: z1_79 | CB13: z1_80 | CC13: z1_81 | CD13: z1_82 | CE13: z1_83 | CF13: z1_84 | CG13: z1_85 | CH13: z1_86 | CI13: z1_87 | CJ13: z1_88 | CK13: z1_89 | CL13: z1_90 | CM13: z1_91 | CN13: z1_92 | CO13: z1_93 | CP13: z1_94 | CQ13: z1_95 | CR13: z1_96 | CS13: z1_97 | CT13: z1_98 | CU13: z1_99 | CV13: z1_100
A14: =MMULT(A10:F10, Pesos!$A$2:$A$7) + Pesos!$A$10 -> -3.279668 | B14: =MMULT(A10:F10, Pesos!$B$2:$B$7) + Pesos!$B$10 -> 5.7337354 | C14: =MMULT(A10:F10, Pesos!$C$2:$C$7) + Pesos!$C$10 -> 14.10465 | D14: =MMULT(A10:F10, Pesos!$D$2:$D$7) + Pesos!$D$10 -> -3.9823132 | E14: =MMULT(A10:F10, Pesos!$E$2:$E$7) + Pesos!$E$10 -> 2.4112551 | F14: =MMULT(A10:F10, Pesos!$F$2:$F$7) + Pesos!$F$10 -> -8.7468983 | G14: =MMULT(A10:F10, Pesos!$G$2:$G$7) + Pesos!$G$10 -> 4.5342455 | H14: =MMULT(A10:F10, Pesos!$H$2:$H$7) + Pesos!$H$10 -> 0.28204507 | I14: =MMULT(A10:F10, Pesos!$I$2:$I$7) + Pesos!$I$10 -> -7.1001655 | J14: =MMULT(A10:F10, Pesos!$J$2:$J$7) + Pesos!$J$10 -> 5.2888144 | K14: =MMULT(A10:F10, Pesos!$K$2:$K$7) + Pesos!$K$10 -> -4.9475615 | L14: =MMULT(A10:F10, Pesos!$L$2:$L$7) + Pesos!$L$10 -> -0.66794129 | M14: =MMULT(A10:F10, Pesos!$M$2:$M$7) + Pesos!$M$10 -> 4.9204216 | N14: =MMULT(A10:F10, Pesos!$N$2:$N$7) + Pesos!$N$10 -> -3.525823 | O14: =MMULT(A10:F10, Pesos!$O$2:$O$7) + Pesos!$O$10 -> 14.833023 | P14: =MMULT(A10:F10, Pesos!$P$2:$P$7) + Pesos!$P$10 -> -3.1475408 | Q14: =MMULT(A10:F10, Pesos!$Q$2:$Q$7) + Pesos!$Q$10 -> 3.0633141 | R14: =MMULT(A10:F10, Pesos!$R$2:$R$7) + Pesos!$R$10 -> 6.3441647 | S14: =MMULT(A10:F10, Pesos!$S$2:$S$7) + Pesos!$S$10 -> 26.316812 | T14: =MMULT(A10:F10, Pesos!$T$2:$T$7) + Pesos!$T$10 -> 7.768386 | U14: =MMULT(A10:F10, Pesos!$U$2:$U$7) + Pesos!$U$10 -> -0.55082562 | V14: =MMULT(A10:F10, Pesos!$V$2:$V$7) + Pesos!$V$10 -> -8.408894 | W14: =MMULT(A10:F10, Pesos!$W$2:$W$7) + Pesos!$W$10 -> -4.251215 | X14: =MMULT(A10:F10, Pesos!$X$2:$X$7) + Pesos!$X$10 -> -1.4715538 | Y14: =MMULT(A10:F10, Pesos!$Y$2:$Y$7) + Pesos!$Y$10 -> -3.1974021 | Z14: =MMULT(A10:F10, Pesos!$Z$2:$Z$7) + Pesos!$Z$10 -> -4.0932438 | AA14: =MMULT(A10:F10, Pesos!$AA$2:$AA$7) + Pesos!$AA$10 -> -1.3294158 | AB14: =MMULT(A10:F10, Pesos!$AB$2:$AB$7) + Pesos!$AB$10 -> 0.58694865 | AC14: =MMULT(A10:F10, Pesos!$AC$2:$AC$7) + Pesos!$AC$10 -> 3.0050576 | AD14: =MMULT(A10:F10, Pesos!$AD$2:$AD$7) + Pesos!$AD$10 -> -2.5465554 | AE14: =MMULT(A10:F10, Pesos!$AE$2:$AE$7) + Pesos!$AE$10 -> 1.2226112 | AF14: =MMULT(A10:F10, Pesos!$AF$2:$AF$7) + Pesos!$AF$10 -> 11.338635 | AG14: =MMULT(A10:F10, Pesos!$AG$2:$AG$7) + Pesos!$AG$10 -> -4.0521674 | AH14: =MMULT(A10:F10, Pesos!$AH$2:$AH$7) + Pesos!$AH$10 -> -3.7363852 | AI14: =MMULT(A10:F10, Pesos!$AI$2:$AI$7) + Pesos!$AI$10 -> 0.032114208 | AJ14: =MMULT(A10:F10, Pesos!$AJ$2:$AJ$7) + Pesos!$AJ$10 -> -2.8082579 | AK14: =MMULT(A10:F10, Pesos!$AK$2:$AK$7) + Pesos!$AK$10 -> -1.6725764 | AL14: =MMULT(A10:F10, Pesos!$AL$2:$AL$7) + Pesos!$AL$10 -> -3.6985706 | AM14: =MMULT(A10:F10, Pesos!$AM$2:$AM$7) + Pesos!$AM$10 -> 1.4664802 | AN14: =MMULT(A10:F10, Pesos!$AN$2:$AN$7) + Pesos!$AN$10 -> 4.6925619 | AO14: =MMULT(A10:F10, Pesos!$AO$2:$AO$7) + Pesos!$AO$10 -> 4.1482897 | AP14: =MMULT(A10:F10, Pesos!$AP$2:$AP$7) + Pesos!$AP$10 -> 8.8217517 | AQ14: =MMULT(A10:F10, Pesos!$AQ$2:$AQ$7) + Pesos!$AQ$10 -> -2.7927285 | AR14: =MMULT(A10:F10, Pesos!$AR$2:$AR$7) + Pesos!$AR$10 -> 10.840984 | AS14: =MMULT(A10:F10, Pesos!$AS$2:$AS$7) + Pesos!$AS$10 -> -8.2084839 | AT14: =MMULT(A10:F10, Pesos!$AT$2:$AT$7) + Pesos!$AT$10 -> -0.43632886 | AU14: =MMULT(A10:F10, Pesos!$AU$2:$AU$7) + Pesos!$AU$10 -> 4.9867753 | AV14: =MMULT(A10:F10, Pesos!$AV$2:$AV$7) + Pesos!$AV$10 -> 1.7598419 | AW14: =MMULT(A10:F10, Pesos!$AW$2:$AW$7) + Pesos!$AW$10 -> 9.1074863 | AX14: =MMULT(A10:F10, Pesos!$AX$2:$AX$7) + Pesos!$AX$10 -> -6.4144687 | AY14: =MMULT(A10:F10, Pesos!$AY$2:$AY$7) + Pesos!$AY$10 -> -8.4200383 | AZ14: =MMULT(A10:F10, Pesos!$AZ$2:$AZ$7) + Pesos!$AZ$10 -> -10.494892 | BA14: =MMULT(A10:F10, Pesos!$BA$2:$BA$7) + Pesos!$BA$10 -> -5.7932993 | BB14: =MMULT(A10:F10, Pesos!$BB$2:$BB$7) + Pesos!$BB$10 -> 1.2442641 | BC14: =MMULT(A10:F10, Pesos!$BC$2:$BC$7) + Pesos!$BC$10 -> 21.123032 | BD14: =MMULT(A10:F10, Pesos!$BD$2:$BD$7) + Pesos!$BD$10 -> 1.3582438 | BE14: =MMULT(A10:F10, Pesos!$BE$2:$BE$7) + Pesos!$BE$10 -> 14.311765 | BF14: =MMULT(A10:F10, Pesos!$BF$2:$BF$7) + Pesos!$BF$10 -> -5.6514117 | BG14: =MMULT(A10:F10, Pesos!$BG$2:$BG$7) + Pesos!$BG$10 -> 6.1096194 | BH14: =MMULT(A10:F10, Pesos!$BH$2:$BH$7) + Pesos!$BH$10 -> -1.711165 | BI14: =MMULT(A10:F10, Pesos!$BI$2:$BI$7) + Pesos!$BI$10 -> -2.279284 | BJ14: =MMULT(A10:F10, Pesos!$BJ$2:$BJ$7) + Pesos!$BJ$10 -> 0.64237926 | BK14: =MMULT(A10:F10, Pesos!$BK$2:$BK$7) + Pesos!$BK$10 -> -1.3462669 | BL14: =MMULT(A10:F10, Pesos!$BL$2:$BL$7) + Pesos!$BL$10 -> -2.6488334 | BM14: =MMULT(A10:F10, Pesos!$BM$2:$BM$7) + Pesos!$BM$10 -> -3.5965394 | BN14: =MMULT(A10:F10, Pesos!$BN$2:$BN$7) + Pesos!$BN$10 -> -3.5613785 | BO14: =MMULT(A10:F10, Pesos!$BO$2:$BO$7) + Pesos!$BO$10 -> 15.450792 | BP14: =MMULT(A10:F10, Pesos!$BP$2:$BP$7) + Pesos!$BP$10 -> -4.5262267 | BQ14: =MMULT(A10:F10, Pesos!$BQ$2:$BQ$7) + Pesos!$BQ$10 -> -4.7424779 | BR14: =MMULT(A10:F10, Pesos!$BR$2:$BR$7) + Pesos!$BR$10 -> -1.1928504 | BS14: =MMULT(A10:F10, Pesos!$BS$2:$BS$7) + Pesos!$BS$10 -> -4.687088 | BT14: =MMULT(A10:F10, Pesos!$BT$2:$BT$7) + Pesos!$BT$10 -> 15.276494 | BU14: =MMULT(A10:F10, Pesos!$BU$2:$BU$7) + Pesos!$BU$10 -> -12.839328 | BV14: =MMULT(A10:F10, Pesos!$BV$2:$BV$7) + Pesos!$BV$10 -> 0.38250835 | BW14: =MMULT(A10:F10, Pesos!$BW$2:$BW$7) + Pesos!$BW$10 -> 21.449073 | BX14: =MMULT(A10:F10, Pesos!$BX$2:$BX$7) + Pesos!$BX$10 -> -2.3827313 | BY14: =MMULT(A10:F10, Pesos!$BY$2:$BY$7) + Pesos!$BY$10 -> -3.4823482 | BZ14: =MMULT(A10:F10, Pesos!$BZ$2:$BZ$7) + Pesos!$BZ$10 -> -0.16328778 | CA14: =MMULT(A10:F10, Pesos!$CA$2:$CA$7) + Pesos!$CA$10 -> -0.57106901 | CB14: =MMULT(A10:F10, Pesos!$CB$2:$CB$7) + Pesos!$CB$10 -> -12.836805 | CC14: =MMULT(A10:F10, Pesos!$CC$2:$CC$7) + Pesos!$CC$10 -> -4.5782129 | CD14: =MMULT(A10:F10, Pesos!$CD$2:$CD$7) + Pesos!$CD$10 -> 3.4665072 | CE14: =MMULT(A10:F10, Pesos!$CE$2:$CE$7) + Pesos!$CE$10 -> 10.840306 | CF14: =MMULT(A10:F10, Pesos!$CF$2:$CF$7) + Pesos!$CF$10 -> 12.069527 | CG14: =MMULT(A10:F10, Pesos!$CG$2:$CG$7) + Pesos!$CG$10 -> 1.4707213 | CH14: =MMULT(A10:F10, Pesos!$CH$2:$CH$7) + Pesos!$CH$10 -> 8.5550087 | CI14: =MMULT(A10:F10, Pesos!$CI$2:$CI$7) + Pesos!$CI$10 -> -1.0322663 | CJ14: =MMULT(A10:F10, Pesos!$CJ$2:$CJ$7) + Pesos!$CJ$10 -> 9.0048717 | CK14: =MMULT(A10:F10, Pesos!$CK$2:$CK$7) + Pesos!$CK$10 -> 5.6918385 | CL14: =MMULT(A10:F10, Pesos!$CL$2:$CL$7) + Pesos!$CL$10 -> 4.7607977 | CM14: =MMULT(A10:F10, Pesos!$CM$2:$CM$7) + Pesos!$CM$10 -> 10.854175 | CN14: =MMULT(A10:F10, Pesos!$CN$2:$CN$7) + Pesos!$CN$10 -> -0.92778169 | CO14: =MMULT(A10:F10, Pesos!$CO$2:$CO$7) + Pesos!$CO$10 -> 8.757805 | CP14: =MMULT(A10:F10, Pesos!$CP$2:$CP$7) + Pesos!$CP$10 -> 1.1679498 | CQ14: =MMULT(A10:F10, Pesos!$CQ$2:$CQ$7) + Pesos!$CQ$10 -> 12.660362 | CR14: =MMULT(A10:F10, Pesos!$CR$2:$CR$7) + Pesos!$CR$10 -> -4.1593009 | CS14: =MMULT(A10:F10, Pesos!$CS$2:$CS$7) + Pesos!$CS$10 -> 5.20712 | CT14: =MMULT(A10:F10, Pesos!$CT$2:$CT$7) + Pesos!$CT$10 -> 7.302587 | CU14: =MMULT(A10:F10, Pesos!$CU$2:$CU$7) + Pesos!$CU$10 -> 16.778288 | CV14: =MMULT(A10:F10, Pesos!$CV$2:$CV$7) + Pesos!$CV$10 -> -3.1586256
A16: h1_1 | B16: h1_2 | C16: h1_3 | D16: h1_4 | E16: h1_5 | F16: h1_6 | G16: h1_7 | H16: h1_8 | I16: h1_9 | J16: h1_10 | K16: h1_11 | L16: h1_12 | M16: h1_13 | N16: h1_14 | O16: h1_15 | P16: h1_16 | Q16: h1_17 | R16: h1_18 | S16: h1_19 | T16: h1_20 | U16: h1_21 | V16: h1_22 | W16: h1_23 | X16: h1_24 | Y16: h1_25 | Z16: h1_26 | AA16: h1_27 | AB16: h1_28 | AC16: h1_29 | AD16: h1_30 | AE16: h1_31 | AF16: h1_32 | AG16: h1_33 | AH16: h1_34 | AI16: h1_35 | AJ16: h1_36 | AK16: h1_37 | AL16: h1_38 | AM16: h1_39 | AN16: h1_40 | AO16: h1_41 | AP16: h1_42 | AQ16: h1_43 | AR16: h1_44 | AS16: h1_45 | AT16: h1_46 | AU16: h1_47 | AV16: h1_48 | AW16: h1_49 | AX16: h1_50 | AY16: h1_51 | AZ16: h1_52 | BA16: h1_53 | BB16: h1_54 | BC16: h1_55 | BD16: h1_56 | BE16: h1_57 | BF16: h1_58 | BG16: h1_59 | BH16: h1_60 | BI16: h1_61 | BJ16: h1_62 | BK16: h1_63 | BL16: h1_64 | BM16: h1_65 | BN16: h1_66 | BO16: h1_67 | BP16: h1_68 | BQ16: h1_69 | BR16: h1_70 | BS16: h1_71 | BT16: h1_72 | BU16: h1_73 | BV16: h1_74 | BW16: h1_75 | BX16: h1_76 | BY16: h1_77 | BZ16: h1_78 | CA16: h1_79 | CB16: h1_80 | CC16: h1_81 | CD16: h1_82 | CE16: h1_83 | CF16: h1_84 | CG16: h1_85 | CH16: h1_86 | CI16: h1_87 | CJ16: h1_88 | CK16: h1_89 | CL16: h1_90 | CM16: h1_91 | CN16: h1_92 | CO16: h1_93 | CP16: h1_94 | CQ16: h1_95 | CR16: h1_96 | CS16: h1_97 | CT16: h1_98 | CU16: h1_99 | CV16: h1_100
A17: =MAX(0, A14) -> 0 | B17: =MAX(0, B14) -> 5.7337354 | C17: =MAX(0, C14) -> 14.10465 | D17: =MAX(0, D14) -> 0 | E17: =MAX(0, E14) -> 2.4112551 | F17: =MAX(0, F14) -> 0 | G17: =MAX(0, G14) -> 4.5342455 | H17: =MAX(0, H14) -> 0.28204507 | ... CV17: =MAX(0, CV14) -> 0
A19: Capa 2 — z2; h2=ReLU(z2)
A20: z2_1 | B20: z2_2 | C20: z2_3 | D20: z2_4 | E20: z2_5 | F20: z2_6 | G20: z2_7 | H20: z2_8 | I20: z2_9 | J20: z2_10 | K20: z2_11 | L20: z2_12 | M20: z2_13 | N20: z2_14 | O20: z2_15 | P20: z2_16 | Q20: z2_17 | R20: z2_18 | S20: z2_19 | T20: z2_20 | U20: z2_21 | V20: z2_22 | W20: z2_23 | X20: z2_24 | Y20: z2_25 | Z20: z2_26 | AA20: z2_27 | AB20: z2_28 | AC20: z2_29 | AD20: z2_30 | AE20: z2_31 | AF20: z2_32 | AG20: z2_33 | AH20: z2_34 | AI20: z2_35 | AJ20: z2_36 | AK20: z2_37 | AL20: z2_38 | AM20: z2_39 | AN20: z2_40 | AO20: z2_41 | AP20: z2_42 | AQ20: z2_43 | AR20: z2_44 | AS20: z2_45 | AT20: z2_46 | AU20: z2_47 | AV20: z2_48 | AW20: z2_49 | AX20: z2_50 | AY20: z2_51 | AZ20: z2_52 | BA20: z2_53 | BB20: z2_54 | BC20: z2_55 | BD20: z2_56 | BE20: z2_57 | BF20: z2_58 | BG20: z2_59 | BH20: z2_60 | BI20: z2_61 | BJ20: z2_62 | BK20: z2_63 | BL20: z2_64 | BM20: z2_65 | BN20: z2_66 | BO20: z2_67 | BP20: z2_68 | BQ20: z2_69 | BR20: z2_70 | BS20: z2_71 | BT20: z2_72 | BU20: z2_73 | BV20: z2_74 | BW20: z2_75 | BX20: z2_76 | BY20: z2_77 | BZ20: z2_78 | CA20: z2_79 | CB20: z2_80 | CC20: z2_81 | CD20: z2_82 | CE20: z2_83 | CF20: z2_84 | CG20: z2_85 | CH20: z2_86 | CI20: z2_87 | CJ20: z2_88 | CK20: z2_89 | CL20: z2_90 | CM20: z2_91 | CN20: z2_92 | CO20: z2_93 | CP20: z2_94 | CQ20: z2_95 | CR20: z2_96 | CS20: z2_97 | CT20: z2_98 | CU20: z2_99 | CV20: z2_100
